order-book/a1-a2-testcases/basic-random.in

    # Random single threaded test case
    
1
o
S 0 AAPL 5877 1
B 1 GOOG 8099 9
S 2 GOOG 1052 16
C 2
B 3 GOOG 2756 17
S 4 GOOG 2756 3
C 0
C 4
S 5 AAPL 8215 16
B 6 GOOG 3354 7
B 7 AMZN 2874 9
S 8 GOOG 8177 16
S 9 GOOG 8874 3
S 10 GOOG 5812 3
B 11 AAPL 3271 12
B 12 AAPL 2182 20
B 13 AAPL 2956 10
S 14 GOOG 1092 8
B 15 AAPL 1405 19
B 16 GOOG 6319 15
B 17 GOOG 5392 2
B 18 AAPL 7823 9
B 19 GOOG 6582 18
B 20 AMZN 3421 2
C 11
S 21 AMZN 4178 20
C 14
B 22 AMZN 2571 18
C 13
C 8
C 3
S 23 AMZN 6416 12
B 24 GOOG 5970 10
S 25 GOOG 1173 6
B 26 AAPL 2284 15
S 27 AMZN 5367 19
B 28 AAPL 1356 7
C 1
S 29 GOOG 4729 16
S 30 AAPL 4095 14
S 31 GOOG 4456 8
S 32 AAPL 7227 10
S 33 AAPL 3824 9
C 12
B 34 AAPL 5394 12
B 35 AMZN 7300 17
S 36 AAPL 8409 17
B 37 AAPL 1868 11
C 34
C 32
C 15
C 24
B 38 GOOG 2503 4
B 39 AMZN 2476 4
B 40 AAPL 5463 8
C 20
B 41 GOOG 5217 1
C 16
S 42 AMZN 8509 9
C 37
C 33
C 7
S 43 GOOG 7219 13
C 30
B 44 GOOG 2752 8
S 45 AAPL 6131 15
B 46 AMZN 3325 13
B 47 AMZN 1767 16
S 48 AMZN 6558 9
C 5
B 49 AMZN 5861 19
C 36
S 50 AMZN 2862 19
S 51 GOOG 8481 15
S 52 GOOG 6497 3
S 53 AMZN 1518 20
S 54 AMZN 7114 6
S 55 AMZN 1424 15
B 56 GOOG 5191 10
S 57 AMZN 1228 1
B 58 AMZN 4209 16
S 59 GOOG 8050 15
S 60 AAPL 7831 17
C 52
S 61 AMZN 8173 7
B 62 AMZN 1942 13
S 63 AAPL 1506 16
C 61
C 42
B 64 AMZN 1991 8
S 65 GOOG 7355 8
C 40
B 66 AMZN 2764 3
C 66
B 67 AMZN 4868 7
C 57
S 68 AMZN 4447 12
B 69 AAPL 8718 1
C 54
C 45
C 31
C 59
B 70 GOOG 5195 2
C 70
S 71 AAPL 4838 10
C 23
S 72 AAPL 7133 7
C 44
S 73 GOOG 4208 13
C 63
B 74 AMZN 6260 11
C 55
S 75 AAPL 3230 8
S 76 AAPL 3147 3
B 77 AMZN 4803 18
B 78 AAPL 7261 6
B 79 AAPL 8680 15
B 80 GOOG 1139 15
B 81 AMZN 3311 16
B 82 AAPL 3670 8
C 27
C 72
B 83 AAPL 7789 15
B 84 GOOG 8550 12
B 85 AAPL 8267 11
C 53
B 86 AMZN 1835 9
S 87 AAPL 3283 9
S 88 GOOG 2101 11
S 89 AAPL 8007 7
S 90 AMZN 4343 6
C 26
B 91 AMZN 1282 19
C 28
C 51
B 92 GOOG 1030 15
S 93 GOOG 1478 2
C 87
B 94 AMZN 2908 16
B 95 GOOG 3826 8
B 96 AAPL 1761 18
C 49
C 22
S 97 AMZN 4471 18
C 60
C 81
C 21
B 98 GOOG 6721 18
S 99 AAPL 5164 18
B 100 AAPL 4626 4
C 77
S 101 AAPL 1962 19
B 102 AMZN 3608 16
C 43
B 103 AAPL 5596 5
C 58
C 83
B 104 GOOG 4910 13
C 47
B 105 AMZN 6976 7
S 106 GOOG 2486 12
C 68
B 107 AMZN 7289 5
B 108 AAPL 1268 8
C 76
B 109 AMZN 7113 13
C 75
B 110 GOOG 7777 17
S 111 AMZN 6547 11
C 108
S 112 AMZN 3398 9
S 113 GOOG 6100 18
S 114 AAPL 8870 19
S 115 GOOG 2393 16
S 116 AMZN 8496 18
C 74
C 46
C 97
S 117 AAPL 1909 19
B 118 GOOG 3726 9
C 115
C 100
S 119 AMZN 5093 16
C 104
S 120 GOOG 8554 18
S 121 GOOG 8073 19
B 122 AMZN 5218 8
C 118
B 123 GOOG 3869 5
B 124 AAPL 6338 3
B 125 GOOG 7460 11
S 126 AAPL 1328 10
B 127 AMZN 2395 9
C 6
S 128 AAPL 6808 3
S 129 AAPL 6487 10
B 130 GOOG 2079 6
B 131 AMZN 2771 6
S 132 AAPL 6195 11
S 133 AMZN 6824 20
S 134 GOOG 5852 2
B 135 AAPL 7642 17
C 91
B 136 AMZN 8249 9
S 137 AMZN 6360 2
S 138 GOOG 4622 12
B 139 AAPL 5608 17
B 140 AAPL 2811 17
S 141 AAPL 7089 3
C 116
S 142 GOOG 7112 17
S 143 AAPL 8886 3
B 144 AMZN 7773 2
S 145 GOOG 1468 12
S 146 GOOG 8997 6
B 147 GOOG 3457 1
B 148 AMZN 5781 2
B 149 AMZN 4623 4
C 111
S 150 AAPL 1877 12
B 151 AAPL 7897 18
S 152 GOOG 4741 6
C 67
C 150
B 153 AMZN 1992 5
C 50
S 154 GOOG 7083 9
B 155 AMZN 6323 1
S 156 GOOG 7997 14
C 82
B 157 AMZN 3374 4
S 158 GOOG 6451 7
S 159 AAPL 5477 3
B 160 AMZN 4608 16
C 157
C 106
C 120
S 161 AAPL 6619 15
B 162 GOOG 6888 11
S 163 AAPL 7457 3
C 160
S 164 AAPL 3109 16
B 165 GOOG 2227 13
B 166 GOOG 7876 18
B 167 AMZN 2203 17
S 168 AAPL 3345 18
B 169 AMZN 4353 7
C 132
C 96
B 170 GOOG 6736 4
C 169
C 149
S 171 AAPL 7601 19
B 172 GOOG 5981 3
C 98
S 173 AAPL 3447 16
C 139
C 84
C 80
S 174 AMZN 1183 14
B 175 AAPL 4458 20
B 176 AMZN 8260 16
B 177 AMZN 5244 13
B 178 AMZN 4283 1
B 179 AMZN 3964 17
S 180 AMZN 8676 8
C 172
C 140
S 181 AMZN 7110 3
C 39
C 88
B 182 GOOG 8986 9
C 48
B 183 AMZN 5677 4
S 184 AMZN 4861 17
C 152
S 185 GOOG 2570 5
S 186 GOOG 1661 14
B 187 GOOG 3452 2
C 159
C 71
C 134
C 166
C 141
B 188 AAPL 7060 5
C 138
S 189 AMZN 6533 3
C 41
S 190 AAPL 6492 7
C 135
C 146
C 124
B 191 GOOG 5627 3
S 192 AAPL 8807 2
B 193 GOOG 3670 18
S 194 GOOG 2806 6
B 195 AMZN 5084 16
C 162
B 196 GOOG 6463 12
C 130
C 176
B 197 AAPL 7997 1
C 154
B 198 AAPL 6528 16
S 199 GOOG 6954 13
S 200 GOOG 8063 8
C 19
B 201 AMZN 5614 13
S 202 AMZN 7640 3
C 180
B 203 GOOG 8208 6
C 131
C 142
S 204 GOOG 6235 20
B 205 GOOG 4837 14
C 161
S 206 AMZN 1065 14
C 167
S 207 GOOG 6107 17
B 208 AMZN 6962 9
C 198
S 209 GOOG 1725 18
C 207
B 210 AMZN 2092 10
B 211 AAPL 5079 8
S 212 AMZN 2882 7
C 136
S 213 GOOG 8393 10
C 158
S 214 AMZN 3363 7
B 215 AAPL 1675 9
S 216 AMZN 5631 20
C 121
B 217 AMZN 2892 5
C 128
B 218 AAPL 4709 10
B 219 AAPL 6254 9
B 220 AMZN 6151 17
C 9
B 221 AAPL 2314 15
C 133
S 222 GOOG 7132 2
C 126
B 223 AMZN 2584 18
S 224 AAPL 3882 18
S 225 GOOG 7295 4
S 226 AAPL 1696 12
S 227 AMZN 8442 3
C 62
C 195
C 79
S 228 AAPL 6058 16
S 229 AMZN 6091 5
S 230 AMZN 2360 7
S 231 GOOG 8429 20
S 232 GOOG 5868 14
S 233 AAPL 1740 19
C 178
B 234 AAPL 5315 18
B 235 AAPL 6977 14
B 236 AMZN 4866 5
C 86
B 237 AAPL 8297 2
B 238 AMZN 2176 12
B 239 AAPL 8320 19
S 240 AMZN 8234 4
B 241 AAPL 1584 1
S 242 GOOG 2424 11
S 243 AMZN 7400 2
S 244 GOOG 1206 8
C 151
B 245 AAPL 7412 17
S 246 AAPL 8266 7
B 247 GOOG 6238 13
C 18
C 221
S 248 AAPL 6621 12
S 249 GOOG 4581 7
S 250 AAPL 2122 8
C 93
C 182
C 196
S 251 AAPL 7190 19
B 252 AMZN 8453 5
C 225
B 253 AMZN 6452 14
B 254 AMZN 6535 10
B 255 GOOG 2917 2
C 107
S 256 AMZN 4299 1
B 257 GOOG 8607 18
S 258 AAPL 4616 4
C 258
C 153
S 259 GOOG 7694 13
S 260 AMZN 6171 18
C 64
S 261 AMZN 4013 5
C 230
B 262 GOOG 7182 16
C 193
S 263 AMZN 6012 10
C 191
S 264 AMZN 3721 2
C 56
S 265 AAPL 6262 3
S 266 GOOG 1841 9
S 267 AAPL 1671 6
S 268 AMZN 2891 7
S 269 GOOG 2048 7
C 244
B 270 GOOG 5941 7
S 271 AMZN 6500 5
B 272 AMZN 7443 13
B 273 GOOG 6768 5
C 272
S 274 AAPL 2523 10
B 275 AMZN 8398 8
C 223
B 276 AAPL 5659 16
S 277 AMZN 7801 16
B 278 AAPL 6855 17
C 213
C 277
S 279 AAPL 6128 16
B 280 AAPL 1913 17
S 281 GOOG 3778 11
S 282 GOOG 3781 16
S 283 GOOG 7874 7
S 284 AAPL 7304 14
B 285 AAPL 6514 9
C 234
B 286 GOOG 5987 2
S 287 AAPL 8756 8
C 184
B 288 AMZN 1110 2
C 143
B 289 AMZN 1322 15
B 290 AMZN 2869 15
B 291 AAPL 3484 13
C 38
C 113
S 292 AMZN 3204 2
B 293 GOOG 5946 14
B 294 GOOG 8006 8
B 295 AAPL 7005 8
S 296 GOOG 5709 8
S 297 AMZN 4117 1
C 145
C 228
B 298 GOOG 7867 1
B 299 AAPL 3112 13
B 300 AMZN 5189 16
B 301 AMZN 7125 14
B 302 AMZN 2611 12
S 303 AAPL 8779 4
S 304 GOOG 5484 19
B 305 AMZN 8673 20
B 306 GOOG 5259 3
B 307 AAPL 2459 19
S 308 GOOG 1647 1
S 309 GOOG 7748 3
S 310 GOOG 3997 12
S 311 AMZN 4036 12
C 127
C 117
C 241
S 312 GOOG 4870 7
C 278
C 307
C 305
C 310
S 313 AAPL 3891 20
S 314 GOOG 1763 2
C 206
C 226
B 315 AMZN 7190 7
B 316 AMZN 3744 16
B 317 AAPL 2543 3
B 318 GOOG 5865 4
S 319 GOOG 3937 16
C 256
C 90
C 25
C 271
C 247
S 320 AMZN 7905 17
S 321 AAPL 5879 16
B 322 AAPL 7972 15
C 262
S 323 AMZN 8094 11
C 231
C 73
B 324 AAPL 3267 7
S 325 AAPL 8346 17
B 326 GOOG 8513 15
B 327 AAPL 6505 15
B 328 GOOG 3089 8
S 329 AMZN 3602 6
S 330 AAPL 5455 11
S 331 AMZN 5354 13
B 332 AMZN 8688 4
B 333 AAPL 7118 18
S 334 AMZN 3496 3
S 335 AMZN 7601 7
B 336 AAPL 5216 16
C 334
C 194
S 337 GOOG 4878 17
C 318
C 217
C 215
S 338 AAPL 7765 6
S 339 GOOG 7721 6
B 340 GOOG 5154 9
B 341 AMZN 8808 8
S 342 AAPL 1757 9
S 343 AMZN 6817 10
B 344 AAPL 7400 16
C 164
C 298
S 345 AMZN 1801 7
B 346 AMZN 2188 6
C 257
S 347 GOOG 5421 12
C 249
B 348 GOOG 6681 13
B 349 AMZN 7776 11
S 350 GOOG 6897 8
C 240
S 351 AAPL 2169 10
B 352 GOOG 2172 12
S 353 AMZN 5712 7
S 354 GOOG 2811 20
S 355 GOOG 4795 17
B 356 GOOG 2074 7
C 214
S 357 AAPL 7923 13
B 358 AAPL 2034 6
S 359 GOOG 2472 3
B 360 AAPL 7836 11
B 361 AMZN 5243 10
C 313
S 362 GOOG 3790 10
S 363 AMZN 4848 4
C 321
B 364 AMZN 3813 1
S 365 AAPL 6296 18
C 325
B 366 AAPL 3780 1
C 190
B 367 AAPL 8638 20
B 368 AAPL 6017 11
B 369 AAPL 4968 2
B 370 AMZN 5162 10
S 371 GOOG 7948 1
S 372 AMZN 8482 6
B 373 AMZN 3830 7
S 374 GOOG 6369 15
B 375 GOOG 5942 5
B 376 AAPL 3115 17
C 114
C 156
B 377 AAPL 4156 20
B 378 AMZN 1476 3
C 17
S 379 GOOG 8661 6
