order-book/a1-a2-testcases/hard-add-cancel-race.in

    # Adds a pair of concurrent orders on the same side, cancels them immediately
    
40
o
0 B 0 INST0 2700 1
0 C 0
20 B 1 INST0 2700 1
20 C 1
0 w 1
20 w 0
0 S 2 INST0 2700 2
0,20 .
1 B 3 INST1 2700 1
1 C 3
21 B 4 INST1 2700 1
21 C 4
1 w 4
21 w 3
1 S 5 INST1 2700 2
1,21 .
2 B 6 INST2 2700 1
2 C 6
22 B 7 INST2 2700 1
22 C 7
2 w 7
22 w 6
2 S 8 INST2 2700 2
2,22 .
3 B 9 INST3 2700 1
3 C 9
23 B 10 INST3 2700 1
23 C 10
3 w 10
23 w 9
3 S 11 INST3 2700 2
3,23 .
4 B 12 INST4 2700 1
4 C 12
24 B 13 INST4 2700 1
24 C 13
4 w 13
24 w 12
4 S 14 INST4 2700 2
4,24 .
5 B 15 INST5 2700 1
5 C 15
25 B 16 INST5 2700 1
25 C 16
5 w 16
25 w 15
5 S 17 INST5 2700 2
5,25 .
6 B 18 INST6 2700 1
6 C 18
26 B 19 INST6 2700 1
26 C 19
6 w 19
26 w 18
6 S 20 INST6 2700 2
6,26 .
7 B 21 INST7 2700 1
7 C 21
27 B 22 INST7 2700 1
27 C 22
7 w 22
27 w 21
7 S 23 INST7 2700 2
7,27 .
8 B 24 INST8 2700 1
8 C 24
28 B 25 INST8 2700 1
28 C 25
8 w 25
28 w 24
8 S 26 INST8 2700 2
8,28 .
9 B 27 INST9 2700 1
9 C 27
29 B 28 INST9 2700 1
29 C 28
9 w 28
29 w 27
9 S 29 INST9 2700 2
9,29 .
10 B 30 INST10 2700 1
10 C 30
30 B 31 INST10 2700 1
30 C 31
10 w 31
30 w 30
10 S 32 INST10 2700 2
10,30 .
11 B 33 INST11 2700 1
11 C 33
31 B 34 INST11 2700 1
31 C 34
11 w 34
31 w 33
11 S 35 INST11 2700 2
11,31 .
12 B 36 INST12 2700 1
12 C 36
32 B 37 INST12 2700 1
32 C 37
12 w 37
32 w 36
12 S 38 INST12 2700 2
12,32 .
13 B 39 INST13 2700 1
13 C 39
33 B 40 INST13 2700 1
33 C 40
13 w 40
33 w 39
13 S 41 INST13 2700 2
13,33 .
14 B 42 INST14 2700 1
14 C 42
34 B 43 INST14 2700 1
34 C 43
14 w 43
34 w 42
14 S 44 INST14 2700 2
14,34 .
15 B 45 INST15 2700 1
15 C 45
35 B 46 INST15 2700 1
35 C 46
15 w 46
35 w 45
15 S 47 INST15 2700 2
15,35 .
16 B 48 INST16 2700 1
16 C 48
36 B 49 INST16 2700 1
36 C 49
16 w 49
36 w 48
16 S 50 INST16 2700 2
16,36 .
17 B 51 INST17 2700 1
17 C 51
37 B 52 INST17 2700 1
37 C 52
17 w 52
37 w 51
17 S 53 INST17 2700 2
17,37 .
18 B 54 INST18 2700 1
18 C 54
38 B 55 INST18 2700 1
38 C 55
18 w 55
38 w 54
18 S 56 INST18 2700 2
18,38 .
19 B 57 INST19 2700 1
19 C 57
39 B 58 INST19 2700 1
39 C 58
19 w 58
39 w 57
19 S 59 INST19 2700 2
19,39 .
0 B 60 INST0 2700 1
0 C 60
20 B 61 INST0 2700 1
20 C 61
0 w 61
20 w 60
0 S 62 INST0 2700 2
0,20 .
1 B 63 INST1 2700 1
1 C 63
21 B 64 INST1 2700 1
21 C 64
1 w 64
21 w 63
1 S 65 INST1 2700 2
1,21 .
2 B 66 INST2 2700 1
2 C 66
22 B 67 INST2 2700 1
22 C 67
2 w 67
22 w 66
2 S 68 INST2 2700 2
2,22 .
3 B 69 INST3 2700 1
3 C 69
23 B 70 INST3 2700 1
23 C 70
3 w 70
23 w 69
3 S 71 INST3 2700 2
3,23 .
4 B 72 INST4 2700 1
4 C 72
24 B 73 INST4 2700 1
24 C 73
4 w 73
24 w 72
4 S 74 INST4 2700 2
4,24 .
5 B 75 INST5 2700 1
5 C 75
25 B 76 INST5 2700 1
25 C 76
5 w 76
25 w 75
5 S 77 INST5 2700 2
5,25 .
6 B 78 INST6 2700 1
6 C 78
26 B 79 INST6 2700 1
26 C 79
6 w 79
26 w 78
6 S 80 INST6 2700 2
6,26 .
7 B 81 INST7 2700 1
7 C 81
27 B 82 INST7 2700 1
27 C 82
7 w 82
27 w 81
7 S 83 INST7 2700 2
7,27 .
8 B 84 INST8 2700 1
8 C 84
28 B 85 INST8 2700 1
28 C 85
8 w 85
28 w 84
8 S 86 INST8 2700 2
8,28 .
9 B 87 INST9 2700 1
9 C 87
29 B 88 INST9 2700 1
29 C 88
9 w 88
29 w 87
9 S 89 INST9 2700 2
9,29 .
10 B 90 INST10 2700 1
10 C 90
30 B 91 INST10 2700 1
30 C 91
10 w 91
30 w 90
10 S 92 INST10 2700 2
10,30 .
11 B 93 INST11 2700 1
11 C 93
31 B 94 INST11 2700 1
31 C 94
11 w 94
31 w 93
11 S 95 INST11 2700 2
11,31 .
12 B 96 INST12 2700 1
12 C 96
32 B 97 INST12 2700 1
32 C 97
12 w 97
32 w 96
12 S 98 INST12 2700 2
12,32 .
13 B 99 INST13 2700 1
13 C 99
33 B 100 INST13 2700 1
33 C 100
13 w 100
33 w 99
13 S 101 INST13 2700 2
13,33 .
14 B 102 INST14 2700 1
14 C 102
34 B 103 INST14 2700 1
34 C 103
14 w 103
34 w 102
14 S 104 INST14 2700 2
14,34 .
15 B 105 INST15 2700 1
15 C 105
35 B 106 INST15 2700 1
35 C 106
15 w 106
35 w 105
15 S 107 INST15 2700 2
15,35 .
16 B 108 INST16 2700 1
16 C 108
36 B 109 INST16 2700 1
36 C 109
16 w 109
36 w 108
16 S 110 INST16 2700 2
16,36 .
17 B 111 INST17 2700 1
17 C 111
37 B 112 INST17 2700 1
37 C 112
17 w 112
37 w 111
17 S 113 INST17 2700 2
17,37 .
18 B 114 INST18 2700 1
18 C 114
38 B 115 INST18 2700 1
38 C 115
18 w 115
38 w 114
18 S 116 INST18 2700 2
18,38 .
19 B 117 INST19 2700 1
19 C 117
39 B 118 INST19 2700 1
39 C 118
19 w 118
39 w 117
19 S 119 INST19 2700 2
19,39 .
0 B 120 INST0 2700 1
0 C 120
20 B 121 INST0 2700 1
20 C 121
0 w 121
20 w 120
0 S 122 INST0 2700 2
0,20 .
1 B 123 INST1 2700 1
1 C 123
21 B 124 INST1 2700 1
21 C 124
1 w 124
21 w 123
1 S 125 INST1 2700 2
1,21 .
2 B 126 INST2 2700 1
2 C 126
22 B 127 INST2 2700 1
22 C 127
2 w 127
22 w 126
2 S 128 INST2 2700 2
2,22 .
3 B 129 INST3 2700 1
3 C 129
23 B 130 INST3 2700 1
23 C 130
3 w 130
23 w 129
3 S 131 INST3 2700 2
3,23 .
4 B 132 INST4 2700 1
4 C 132
24 B 133 INST4 2700 1
24 C 133
4 w 133
24 w 132
4 S 134 INST4 2700 2
4,24 .
5 B 135 INST5 2700 1
5 C 135
25 B 136 INST5 2700 1
25 C 136
5 w 136
25 w 135
5 S 137 INST5 2700 2
5,25 .
6 B 138 INST6 2700 1
6 C 138
26 B 139 INST6 2700 1
26 C 139
6 w 139
26 w 138
6 S 140 INST6 2700 2
6,26 .
7 B 141 INST7 2700 1
7 C 141
27 B 142 INST7 2700 1
27 C 142
7 w 142
27 w 141
7 S 143 INST7 2700 2
7,27 .
8 B 144 INST8 2700 1
8 C 144
28 B 145 INST8 2700 1
28 C 145
8 w 145
28 w 144
8 S 146 INST8 2700 2
8,28 .
9 B 147 INST9 2700 1
9 C 147
29 B 148 INST9 2700 1
29 C 148
9 w 148
29 w 147
9 S 149 INST9 2700 2
9,29 .
10 B 150 INST10 2700 1
10 C 150
30 B 151 INST10 2700 1
30 C 151
10 w 151
30 w 150
10 S 152 INST10 2700 2
10,30 .
11 B 153 INST11 2700 1
11 C 153
31 B 154 INST11 2700 1
31 C 154
11 w 154
31 w 153
11 S 155 INST11 2700 2
11,31 .
12 B 156 INST12 2700 1
12 C 156
32 B 157 INST12 2700 1
32 C 157
12 w 157
32 w 156
12 S 158 INST12 2700 2
12,32 .
13 B 159 INST13 2700 1
13 C 159
33 B 160 INST13 2700 1
33 C 160
13 w 160
33 w 159
13 S 161 INST13 2700 2
13,33 .
14 B 162 INST14 2700 1
14 C 162
34 B 163 INST14 2700 1
34 C 163
14 w 163
34 w 162
14 S 164 INST14 2700 2
14,34 .
15 B 165 INST15 2700 1
15 C 165
35 B 166 INST15 2700 1
35 C 166
15 w 166
35 w 165
15 S 167 INST15 2700 2
15,35 .
16 B 168 INST16 2700 1
16 C 168
36 B 169 INST16 2700 1
36 C 169
16 w 169
36 w 168
16 S 170 INST16 2700 2
16,36 .
17 B 171 INST17 2700 1
17 C 171
37 B 172 INST17 2700 1
37 C 172
17 w 172
37 w 171
17 S 173 INST17 2700 2
17,37 .
18 B 174 INST18 2700 1
18 C 174
38 B 175 INST18 2700 1
38 C 175
18 w 175
38 w 174
18 S 176 INST18 2700 2
18,38 .
19 B 177 INST19 2700 1
19 C 177
39 B 178 INST19 2700 1
39 C 178
19 w 178
39 w 177
19 S 179 INST19 2700 2
19,39 .
0 B 180 INST0 2700 1
0 C 180
20 B 181 INST0 2700 1
20 C 181
0 w 181
20 w 180
0 S 182 INST0 2700 2
0,20 .
1 B 183 INST1 2700 1
1 C 183
21 B 184 INST1 2700 1
21 C 184
1 w 184
21 w 183
1 S 185 INST1 2700 2
1,21 .
2 B 186 INST2 2700 1
2 C 186
22 B 187 INST2 2700 1
22 C 187
2 w 187
22 w 186
2 S 188 INST2 2700 2
2,22 .
3 B 189 INST3 2700 1
3 C 189
23 B 190 INST3 2700 1
23 C 190
3 w 190
23 w 189
3 S 191 INST3 2700 2
3,23 .
4 B 192 INST4 2700 1
4 C 192
24 B 193 INST4 2700 1
24 C 193
4 w 193
24 w 192
4 S 194 INST4 2700 2
4,24 .
5 B 195 INST5 2700 1
5 C 195
25 B 196 INST5 2700 1
25 C 196
5 w 196
25 w 195
5 S 197 INST5 2700 2
5,25 .
6 B 198 INST6 2700 1
6 C 198
26 B 199 INST6 2700 1
26 C 199
6 w 199
26 w 198
6 S 200 INST6 2700 2
6,26 .
7 B 201 INST7 2700 1
7 C 201
27 B 202 INST7 2700 1
27 C 202
7 w 202
27 w 201
7 S 203 INST7 2700 2
7,27 .
8 B 204 INST8 2700 1
8 C 204
28 B 205 INST8 2700 1
28 C 205
8 w 205
28 w 204
8 S 206 INST8 2700 2
8,28 .
9 B 207 INST9 2700 1
9 C 207
29 B 208 INST9 2700 1
29 C 208
9 w 208
29 w 207
9 S 209 INST9 2700 2
9,29 .
10 B 210 INST10 2700 1
10 C 210
30 B 211 INST10 2700 1
30 C 211
10 w 211
30 w 210
10 S 212 INST10 2700 2
10,30 .
11 B 213 INST11 2700 1
11 C 213
31 B 214 INST11 2700 1
31 C 214
11 w 214
31 w 213
11 S 215 INST11 2700 2
11,31 .
12 B 216 INST12 2700 1
12 C 216
32 B 217 INST12 2700 1
32 C 217
12 w 217
32 w 216
12 S 218 INST12 2700 2
12,32 .
13 B 219 INST13 2700 1
13 C 219
33 B 220 INST13 2700 1
33 C 220
13 w 220
33 w 219
13 S 221 INST13 2700 2
13,33 .
14 B 222 INST14 2700 1
14 C 222
34 B 223 INST14 2700 1
34 C 223
14 w 223
34 w 222
14 S 224 INST14 2700 2
14,34 .
15 B 225 INST15 2700 1
